Workbook
Name A_DOM: inputoutput!$C$74:$W$94
Name a_dom_elec: electricity!$D$276:$M$296
Name A_IMP_SH: inputoutput!$C$97:$W$117
Name a_imp_sh_elec: electricity!$D$255:$M$275
Name Abruzzo_alpha: regions!$C$142:$I$142
Name Abruzzo_yd: regions!$C$119:$I$119
Name avg_hh_members: regions!$Q$154:$Q$173
Name Basilicata_alpha: regions!$C$146:$I$146
Name Basilicata_yd: regions!$C$123:$I$123
Name beta_q1: regions!$AZ$3:$BO$22
Name beta_q2: regions!$AZ$23:$BO$42
Name beta_q3: regions!$AZ$43:$BO$62
Name beta_q4: regions!$AZ$63:$BO$82
Name beta_q5: regions!$AZ$83:$BO$102
Name Calabria_alpha: regions!$C$147:$I$147
Name Calabria_yd: regions!$C$124:$I$124
Name Campania_alpha: regions!$C$144:$I$144
Name Campania_yd: regions!$C$121:$I$121
Name cap_const_init: electricity!$E$104:$E$112
Name cap_constr_init: electricity!$E$104:$E$112
Name cap_init: electricity!$E$95:$E$103
Name cap_prod_i: investments!#REF!
Name capwealth: finance!$E$7
Name cat_shares_q1: regions!$V$3:$AT$22
Name cat_shares_q2: regions!$V$23:$AT$42
Name cat_shares_q3: regions!$V$43:$AT$62
Name cat_shares_q4: regions!$V$63:$AT$82
Name cat_shares_q5: regions!$V$83:$AT$102
Name cf_final: electricity!$E$75:$E$83
Name child_shares_q1: regions!$AU$3:$AU$22
Name child_shares_q2: regions!$AU$23:$AU$42
Name child_shares_q3: regions!$AU$43:$AU$62
Name child_shares_q4: regions!$AU$63:$AU$82
Name child_shares_q5: regions!$AU$83:$AU$102
Name coeff_inc: prices!$Z$9:$Z$29
Name coeff_inc2: prices!$AA$9:$AA$29
Name coeff_prices: prices!$AB$9:$AV$29
Name coicop_to_ind: consumption!$B$27:$Q$47
Name cons_coicop_initial: consumption!$B$52:$Q$52
Name cons_p_initial: consumption!$B$150:$Q$150
Name cons_shocks: covid!$B$25:$O$25
Name constant: prices!$Y$9:$Y$29
Name conversion_eff: electricity!$U$192:$U$195
Name covid_cons_2020: covid!$B$9
Name covid_cons_2021: covid!$C$9
Name covid_cons_2022: covid!$D$9
Name covid_exp_2020: covid!$B$15
Name covid_exp_2021: covid!$C$15
Name covid_exp_2022: covid!$D$15
Name covid_gov_2020: covid!$B$12
Name covid_gov_2021: covid!$C$12
Name covid_gov_2022: covid!$D$12
Name covid_inv_2020: covid!$B$18
Name covid_inv_2021: covid!$C$18
Name covid_inv_2022: covid!$D$18
Name covid_lfpr_2020: covid!$B$5:$D$6
Name covid_lfpr_2021: covid!$E$5:$G$6
Name covid_lfpr_2022: covid!$H$5:$J$6
Name covid_rebound: covid!$C$29:$C$49
Name covid_shock: covid!$B$29:$B$49

Sheet Info
F4: INDEX OF DATA HERE
D9: Data country | E9: Italy
D11: Sheets
D13: Category | E13: Sheet link | F13: Description | H13: NOT FINISHED SHEET
D14: Economy | E14: =HYPERLINK("#'inputoutput'!A1", "inputoutput") -> inputoutput | F14: Input-output tables and sectoral data
D15: Economy | E15: =HYPERLINK("#'internationaltrade'!A1", "internationaltrade") -> internationaltrade | F15: Data on imports and exports
D16: Economy | E16: =HYPERLINK("#'prices'!A1", "prices") -> prices | F16: Inflation-related data
D17: Economy | E17: =HYPERLINK("#'consumption'!A1", "consumption") -> consumption | F17: Consumption expenditure related data
D18: Economy | E18: =HYPERLINK("#'beta_elasticities'!A1", "beta_elasticities") -> beta_elasticities | F18: Data on elasticity estimates
D19: Economy | E19: =HYPERLINK("#'investments'!A1", "investments") -> investments | F19: Data on capital formation and investments
D20: Economy | E20: regions | F20: Data specific to regions and relative quintiles
D21: Economy | E21: =HYPERLINK("#'finance'!A1", "finance") -> finance | F21: Wealth and interest rate
D22: Economy | E22: =HYPERLINK("#'labour'!A1", "labour") -> labour | F22: Labor market data including employment and wages
D23: Economy | E23: =HYPERLINK("#'government'!A1", "government") -> government | F23: Government spending and tax revenues | K23: Vensim code for referring to Excel data
D24: Economy | E24: =HYPERLINK("#'technology'!A1", "technology") -> technology | F24: Data on productivity | K24: GET_XLS_CONSTANTS('?InputData', 'inputoutput', 'A1')
D25: Demography | E25: =HYPERLINK("#'timeuse'!A1", "timeuse") -> timeuse | F25: Data on time use | K25: GET_XLS_CONSTANTS('?InputData', '', '')
D26: Demography | E26: =HYPERLINK("#'demography'!A1", "demography") -> demography | F26: Population, age, and demographic structure and trends
D27: Demography | E27: =HYPERLINK("#'migration'!A1", "migration") -> migration | F27: Data on migration patterns
D28: Environment | E28: =HYPERLINK("#'energy'!A1", "energy") -> energy | F28: Data on energy production, consumption, and efficiency
D29: Environment | E29: =HYPERLINK("#'electricity'!A1", "electricity") -> electricity | F29: Data on electricity generation, distribution, and consumption
D30: Environment | E30: =HYPERLINK("#'emissions'!A1", "emissions") -> emissions | F30: Data on greenhouse gas emissions from economic activity
D31: Environment | E31: =HYPERLINK("#'emissionstrading'!A1", "emissionstrading") -> emissionstrading | F31: Data on emissions trading systems and policies
D32: Environment | E32: =HYPERLINK("#'temperature'!A1", "temperature") -> temperature | F32: Climate change projections
D33: Environment | E33: =HYPERLINK("#'speciesrichness'!A1", "speciesrichness") -> speciesrichness | F33: Species richness related data
D34: Environment | E34: =HYPERLINK("#'ecosystemservices'!A1", "ecosystemservices") -> ecosystemservices | F34: Ecosystem services related data
D35: Environment | E35: =HYPERLINK("#'ecostressors'!A1", "ecostressors") -> ecostressors | F35: Data on the drivers of biodiversity loss and ecological degradation
B82: Consumption categories
C84: COICOP code | D84: Category | F84: Matching Cazcarro et al. 2022 categories | H84: Model abbreviation
B85: 1 | C85: CP01 | D85: Food and non-alcoholic beverages | F85: CP011, CP012
B86: 2 | C86: CP02 | D86: Alcoholic beverages, tobacco and narcotics | F86: CP021, CP022, CP023
B87: 3 | C87: CP03 | D87: Clothing and footwear | F87: CP031, CP032
B88: 4 | C88: CP041 – 043 | D88: Housing (actual and imputed rentals, maintenance and repair of the dwelling) | F88: CP041, CP042, CP043
B89: 5 | C89: CP044 | D89: Water supply and miscellaneous services relating to the dwelling | F89: CP044
B90: 6 | C90: CP045 | D90: Electricity, gas and other fuels | F90: CP045
B91: 7 | C91: CP05 | D91: Furnishings, household equipment and routine household maintenance | F91: CP051, CP052, CP053, CP054, CP055, CP056 (non-durable household goods)
B92: 8 | C92: CP06 | D92: Health | F92: CP061, CP062, CP063
B93: 9 | C93: CP071 – 072 | D93: Private transport | F93: CP071, CP072
B94: 10 | C94: CP073 | D94: Transport services | F94: CP073
B95: 11 | C95: CP08 | D95: Communications | F95: CP081, CP082, CP083
B96: 12 | C96: CP09 | D96: Recreation and culture | F96: CP091, CP092, CP093, CP094, CP095, CP096
...

Sheet Indexes
A1: Index of ranges | B1: Description | C1: Sheet | D1: Original file
A2: A_DOM | B2: Domestic techinal coefficients matrix (not imported intermediate inputs) | C2: Inputoutput | D2: Inputoutput
A3: a_dom_elec | B3: A columns electricity | C3: Electricity | D3: electricity_module_data
A4: A_IMP_SH | B4: Import shares of input-output table | C4: Inputoutput | D4: Inputoutput
A5: a_imp_sh_elec | B5: A columns electricity import share | C5: Electricity | D5: electricity_module_data
A6: Abruzzo_alpha | B6: Abruzzo average propensity to consume | C6: regions | D6: elasticities
A7: Abruzzo_yd | B7: Abruzzo mean disposable income by quintile | C7: regions | D7: elasticities
A8: avg_hh_members | B8: average number of household members per region | C8: regions | D8: elasticities
A9: Basilicata_alpha | B9: Basilicata average propensity to consume | C9: regions | D9: elasticities
A10: Basilicata_yd | B10: Basilicata mean disposable income by quintile | C10: regions | D10: elasticities
A11: Calabria_alpha | B11: Calabria average propensity to consume | C11: regions | D11: elasticities
A12: Calabria_yd | B12: Calabria mean disposable income by quintile | C12: regions | D12: elasticities
... A17: cap_init | B17: capacity initial MW | C17: Electricity | D17: electricity_module_data
A18: cat_shares_q1 | B18: Region-quintile population shares per individual type, quintile 1 | C18: regions
A19: cat_shares_q2 | B19: Region-quintile population shares per individual type, quintile 2 | C19: regions
A20: cat_shares_q3 | B20: Region-quintile population shares per individual type, quintile 3 | C20: regions
A21: cat_shares_q4 | B21: Region-quintile population shares per individual type, quintile 4 | C21: regions
A22: cat_shares_q5 | B22: Region-quintile population shares per individual type, quintile 5 | C22: regions
A23: cf_final | B23: implicit final capacity factor techn | C23: Electricity | D23: electricity_module_data
A24: child_shares_q1 | B24: Region-quintile population shares for children, quintile 1 | C24: regions
A25: child_shares_q2 | B25: Region-quintile population shares for children, quintile 2 | C25: regions
A26: child_shares_q3 | B26: Region-quintile population shares for children, quintile 3 | C26: regions
A27: child_shares_q4 | B27: Region-quintile population shares for children, quintile 4 | C27: regions
A28: child_shares_q5 | B28: Region-quintile population shares for children, quintile 5 | C28: regions
A29: coeff_inc | B29: demand system coefficients of income | C29: prices | D29: aids
A30: coeff_prices | B30: demand system coefficients of prices | C30: prices | D30: aids
A31: coicop_to_ind | B31: Bridge matrix to convert consumption shares in coicop to consumption shares in industries | C31: consumption | D31: NACE_COICOP_bridge
A32: cons_coicop_initial | B32: Initial total consumption per coicop category | C32: consumption | D32: NACE_COICOP_bridge
A33: cons_shocks | B33: Covid shock on consumption | C33: covid | D33: elasticities
A34: constant | B34: intercept | C34: prices | D34: aids
A35: conversion_eff | B35: Fuel conversion intensities | C35: Electricity | D35: electricity_module_data
A36: covid_cons_2020 | B36: 2020 household consumption | C36: covid | D36: elasticities
A37: covid_cons_2021 | B37: 2021 household consumption | C37: covid | D37: elasticities
A38: covid_cons_2022 | B38: 2022 household consumption | C38: covid | D38: elasticities
A39: covid_exp_2020 | B39: 2020 Exports | C39: covid | D39: elasticities
A40: covid_exp_2021 | B40: 2021 Exports | C40: covid | D40: elasticities
... A179: SOU_SH_Z_IMP_OIL | B179: imported Share of oil in aggregate demand per industry | C179: Energy | D179: Energy_IO
A180: spread_italy | B180: RANGE NOT NAMED
A181: storage_final_cf | B181: final capacity factor storage | C181: Electricity | D181: electricity_module_data
A182: storage_init_cap_constr | B182: constructed initial capacity storage | C182: Electricity | D182: electricity_module_data
...

Sheet inputoutput
B1: FinDEm
D2: H | E2: G | F2: GFCF | G2: EXP
B3: dom | C3: A | D3: 1.4416841e+10 | E3: 4.7972462e+08 | F3: 4.0608227e+08 | G3: 5.2329747e+09
C4: B | D4: 1.164663e+09 | E4: 3288825.7 | F4: 1.6377672e+08 | G4: 9.5719296e+08
C5: C | D5: 9.5006733e+10 | E5: 2.1869734e+09 | F5: 4.5901407e+10 | G5: 2.5500605e+11
C6: C19 | D6: 1.4517121e+10 | E6: 10980248 | F6: 93374541 | G6: 1.1821832e+10
C7: C29 | D7: 1.0586266e+10 | E7: 59873342 | F7: 9.2033302e+09 | G7: 3.5156602e+10
C8: D1 | D8: 7.3176546e+09 | E8: 70756542 | F8: 8.9421805e+08 | G8: 4.7859998e+08
C9: D2 | D9: 8.4466889e+09 | E9: 14910176 | F9: 2.9239688e+08 | G9: 1.9708284e+08
C10: D3 | D10: 14044283 | E10: 15144529 | F10: 1.8463643e+08 | G10: 56104519
C11: E | D11: 1.0862805e+10 | E11: 3.03743e+08 | F11: 2.5860767e+08 | G11: 1.4250849e+09
C12: F | D12: 1.0850175e+10 | E12: 1.2946198e+09 | F12: 1.4143045e+11 | G12: 9.1158893e+08
C13: G | D13: 1.6414656e+11 | E13: 4.3692152e+09 | F13: 2.2544659e+10 | G13: 1.5634335e+10
C14: H | D14: 3.2267459e+10 | E14: 1.2654147e+09 | F14: 1.7775158e+09 | G14: 8.918932e+09
C15: I | D15: 7.7737627e+10 | E15: 8.5012791e+08 | F15: 1.0748647e+08 | G15: 47163108
... C23: T | D23: 1.80064e+10 | E23: 0 | F23: 0 | G23: 0
B24: imp | C24: A | D24: 3.8571939e+09 | E24: 8869778.8 | F24: 53508701
C25: B | D25: 7.5556145e+09 | E25: 5355273 | F25: 80203419
C26: C | D26: 5.114509e+10 | E26: 3.3490343e+09 | F26: 2.1619501e+10
C27: C19 | D27: 2.0777718e+09 | E27: 20799641 | F27: 19307961
C28: C29 | D28: 1.2135246e+10 | E28: 6441454.1 | F28: 7.7898918e+09
C29: D1 | D29: 1.0164527e+08 | E29: 1405739 | F29: 24526902
C30: D2 | D30: 3.1838339e+08 | E30: 4926155.2 | F30: 4621876.1
C31: D3 | D31: 8001390.9 | E31: 99246.537 | F31: 992552.88
C32: E | D32: 35242220 | E32: 2587522.4 | F32: 9728063.9
C33: F | D33: 1.0974863e+08 | E33: 8809900.8 | F33: 79085531
C34: G | D34: 8.1036708e+09 | E34: 5.7425589e+08 | F34: 2.1919856e+09
C35: H | D35: 4.3970601e+09 | E35: 1.0409825e+08 | F35: 2.0800501e+08
C36: I | D36: 1.1695584e+09 | E36: 15389552 | F36: 1589731.6
... C44: T | D44: 438497.15 | E44: 132081.35 | F44: 26290.697
B45: import shares | C45: A | D45: 0.21107511 | E45: 0.018153664 | F45: 0.11642679
C46: B | D46: 0.86644198 | E46: 0.61952937 | F46: 0.32872929
C47: C | D47: 0.34994493 | E47: 0.60495477 | F47: 0.32018973
C48: C19 | D48: 0.1252055 | E48: 0.65449067 | F48: 0.17134835
C49: C29 | D49: 0.5340862 | E49: 0.097134492 | F49: 0.4584117
C50: D1 | D50: 0.013700116 | E50: 0.019480246 | F50: 0.026696094
C51: D2 | D51: 0.036324103 | E51: 0.24834003 | F51: 0.01556089
C52: D3 | D52: 0.36294608 | E52: 0.006510627 | F52: 0.0053469714
C53: E | D53: 0.0032338106 | E53: 0.0084468318 | F53: 0.03625333
C54: F | D54: 0.010013631 | E54: 0.0067590147 | F54: 0.0005588707
...

Sheet internationaltrade
A1: Z imp | C1: A1 | D1: A2 | E1: A3 | F1: B | G1: C10_12 | H1: C13_15 | I1: C16_17 | J1: C20_22 | K1: C19 | L1: C23 | M1: C24_33 | N1: C26_27 | O1: C31_32 | P1: D | Q1: E | R1: F | S1: G | T1: H | U1: I | V1: J | W1: K | X1: L | Y1: M_N | Z1: M_N_72 | AA1: M_N_73 | AB1: O | AC1: P | AD1: Q | AE1: R | AF1: S95 | AG1: ST
B2: A1 | C2: 69670000 | D2: 0 | E2: 0 | F2: 0 | G2: 277890000 | H2: 70000 | I2: 140000 | J2: 63260000 | K2: 0 | L2: 0 | M2: 0 | N2: 0 | O2: 220000 | P2: 0 | Q2: 0 | R2: 20000 | S2: 0 | T2: 0 | U2: 34580000 | V2: 0 | W2: 0 | X2: 0 | Y2: 830000 | Z2: 0 | AA2: 0 | AB2: 7320000 | AC2: 3020000 | AD2: 6370000 | AE2: 750000 | AF2: 0 | AG2: 110000
B3: A2 | C3: 130000 | D3: 3040000 | E3: 0 | F3: 0 | G3: 4630000 | H3: 0 | I3: 332020000 | J3: 0 | K3: 0 | L3: 0 | M3: 5460000 | N3: 0 | O3: 20000 | P3: 19230000 | Q3: 0 | R3: 180000 | S3: 180000 | T3: 0 | U3: 0 | V3: 0 | W3: 0 | X3: 230000 | Y3: 30000 | Z3: 0 | AA3: 0 | AB3: 300000 | AC3: 120000 | AD3: 270000 | AE3: 30000 | AF3: 0 | AG3: 0
B4: A3 | C4: 140000 | D4: 120000 | E4: 510000 | F4: 0 | G4: 33200000 | H4: 0 | I4: 0 | J4: 0 | K4: 0 | L4: 0 | M4: 0 | N4: 0 | O4: 0 | P4: 200000 | Q4: 150000 | R4: 930000 | S4: 1150000 | T4: 3190000 | U4: 44420000 | V4: 1660000 | W4: 730000 | X4: 1000000 | Y4: 3020000 | Z4: 80000 | AA4: 480000 | AB4: 3160000 | AC4: 1200000 | AD4: 2630000 | AE4: 620000 | AF4: 0 | AG4: 1020000
B5: B | C5: 780000 | D5: 0 | E5: 0 | F5: 9860000 | G5: 7930000 | H5: 410000 | I5: 139800000 | J5: 135740000 | K5: 4831730000 | L5: 48500000 | M5: 9.1365e+08 | N5: 40000 | O5: 270000 | P5: 1153250000 | Q5: 280000 | R5: 16030000 | S5: 16030000 | T5: 0 | U5: 0 | V5: 0 | W5: 0 | X5: 0 | Y5: 10000 | Z5: 0 | AA5: 0 | AB5: 20000 | AC5: 10000 | AD5: 0 | AE5: 0 | AF5: 0 | AG5: 0
B6: C10_12 | C6: 40500000 | D6: 1610000 | E6: 10000 | F6: 0 | G6: 521500000 | H6: 1180000 | I6: 37510000 | J6: 214400000 | K6: 51410000 | L6: 330000 | M6: 0 | N6: 0 | O6: 20000 | P6: 5710000 | Q6: 1560000 | R6: 10090000 | S6: 12470000 | T6: 33400000 | U6: 225660000 | V6: 19320000 | W6: 7400000 | X6: 12160000 | Y6: 38050000 | Z6: 970000 | AA6: 5570000 | AB6: 91820000 | AC6: 28880000 | AD6: 60890000 | AE6: 10600000 | AF6: 300000 | AG6: 13230000
B7: C13_15 | C7: 360000 | D7: 360000 | E7: 0 | F7: 670000 | G7: 4530000 | H7: 301590000 | I7: 30410000 | J7: 14710000 | K7: 0 | L7: 17880000 | M7: 28310000 | N7: 6600000 | O7: 24460000 | P7: 1480000 | Q7: 14630000 | R7: 25100000 | S7: 41030000 | T7: 20950000 | U7: 4020000 | V7: 12260000 | W7: 6230000 | X7: 2800000 | Y7: 53860000 | Z7: 990000 | AA7: 5900000 | AB7: 49740000 | AC7: 1220000 | AD7: 39550000 | AE7: 1120000 | AF7: 4690000 | AG7: 8920000
B8: C16_17 | C8: 640000 | D8: 1350000 | E8: 0 | F8: 300000 | G8: 70220000 | H8: 1500000 | I8: 536480000 | J8: 27600000 | K8: 210000 | L8: 11290000 | M8: 14740000 | N8: 4000000 | O8: 45400000 | P8: 4150000 | Q8: 2140000 | R8: 290730000 | S8: 301490000 | T8: 8020000 | U8: 1240000 | V8: 20840000 | W8: 7730000 | X8: 7180000 | Y8: 47620000 | Z8: 3290000 | AA8: 3410000 | AB8: 40490000 | AC8: 36480000 | AD8: 29030000 | AE8: 10520000 | AF8: 1500000 | AG8: 13600000
B9: C20_22 | C9: 182720000 | D9: 34840000 | E9: 0 | F9: 42080000 | G9: 288310000 | H9: 80530000 | I9: 718720000 | J9: 1399530000 | K9: 68090000 | L9: 80480000 | M9: 239290000 | N9: 1.0835e+08 | O9: 51540000 | P9: 278510000 | Q9: 77100000 | R9: 479580000 | S9: 549260000 | T9: 1.5765e+08 | U9: 1050000 | V9: 9660000 | W9: 3030000 | X9: 2260000 | Y9: 143110000 | Z9: 420000 | AA9: 11720000 | AB9: 60330000 | AC9: 38700000 | AD9: 6.3355e+08 | AE9: 18300000 | AF9: 2060000 | AG9: 41520000
B10: C19 | C10: 62060000 | D10: 37270000 | E10: 530000 | F10: 21130000 | G10: 3100000 | H10: 280000 | I10: 20180000 | J10: 3.1455e+08 | K10: 699640000 | L10: 28720000 | M10: 144610000 | N10: 5410000 | O10: 5110000 | P10: 150950000 | Q10: 7000000 | R10: 119560000 | S10: 137120000 | T10: 509220000 | U10: 2230000 | V10: 3540000 | W10: 6760000 | X10: 1.781e+08 | Y10: 22810000 | Z10: 1380000 | AA10: 20000 | AB10: 48650000 | AC10: 13250000 | AD10: 14000000 | AE10: 4770000 | AF10: 280000 | AG10: 5870000
B11: C23 | C11: 750000 | D11: 0 | E11: 0 | F11: 6170000 | G11: 19380000 | H11: 660000 | I11: 33520000 | J11: 21730000 | K11: 0 | L11: 103690000 | M11: 64620000 | N11: 12510000 | O11: 9830000 | P11: 380000 | Q11: 440000 | R11: 224470000 | S11: 250990000 | T11: 30000 | U11: 60000 | V11: 1290000 | W11: 720000 | X11: 20000 | Y11: 4060000 | Z11: 80000 | AA11: 720000 | AB11: 50000 | AC11: 190000 | AD11: 10060000 | AE11: 60000 | AF11: 190000 | AG11: 1390000
B12: C24_33 | C12: 57650000 | D12: 6250000 | E12: 150000 | F12: 27250000 | G12: 91720000 | H12: 530000 | I12: 46290000 | J12: 35610000 | K12: 3990000 | L12: 30830000 | M12: 3661330000 | N12: 1.1701e+08 | O12: 23730000 | P12: 1600000 | Q12: 52100000 | R12: 898520000 | S12: 1130520000 | T12: 3.795e+08 | U12: 960000 | V12: 65860000 | W12: 2540000 | X12: 510000 | Y12: 34210000 | Z12: 1690000 | AA12: 1780000 | AB12: 85910000 | AC12: 14640000 | AD12: 320000 | AE12: 1490000 | AF12: 4570000 | AG12: 2340000
B13: C26_27 | C13: 110000 | D13: 110000 | E13: 0 | F13: 0 | G13: 0 | H13: 50000 | I13: 2000000 | J13: 10910000 | K13: 0 | L13: 7400000 | M13: 622000000 | N13: 2912060000 | O13: 16330000 | P13: 610000 | Q13: 14720000 | R13: 4.5241e+08 | S13: 5.2317e+08 | T13: 28290000 | U13: 230000 | V13: 166940000 | W13: 1.7841e+08 | X13: 1880000 | Y13: 484410000 | Z13: 16370000 | AA13: 58620000 | AB13: 73280000 | AC13: 54260000 | AD13: 1.3147e+08 | AE13: 33880000 | AF13: 28220000 | AG13: 13170000
... B32: ST | C32: 0 | D32: 0 | E32: 0 | F32: 0 | G32: 0 | H32: 0 | I32: 0 | J32: 0 | K32: 0 | L32: 0 | M32: 0 | N32: 0 | O32: 0 | P32: 0 | Q32: 0 | R32: 0 | S32: 0 | T32: 0 | U32: 0 | V32: 0 | W32: 0 | X32: 0 | Y32: 0 | Z32: 0 | AA32: 0 | AB32: 0 | AC32: 0 | AD32: 0 | AE32: 0 | AF32: 0 | AG32: 0
C35: A1 | D35: A2 | E35: A3 | F35: B | G35: C10_12 | H35: C13_15 | I35: C16_17 | J35: C18 | K35: C20_22 | L35: C19 | M35: C23 | N35: C24_33 | O35: C26_27 | P35: C31_32 | Q35: D | R35: E | S35: F | T35: G | U35: H | V35: I | W35: J | X35: K | Y35: L | Z35: M_N | AA35: M_N_72 | AB35: M_N_73 | AC35: O | AD35: P | AE35: Q | AF35: R | AG35: S95 | AH35: ST | AI35: TOT
B36: EXP | C36: 4.74186e+08 | D36: 44825000 | E36: 17441000 | F36: 383252000 | G36: 1408114000 | H36: 607495000 | I36: 10980171000 | K36: 5.747783e+09 | L36: 3620733000 | M36: 6.34111e+08 | N36: 1.8500951e+10 | O36: 14182868000 | P36: 503411000 | Q36: 604495000 | R36: 2.73761e+08 | S36: 9332000 | T36: 1.293011e+09 | U36: 3.640756e+09 | V36: 184691000 | W36: 2.715785e+09 | X36: 6.3953e+08 | Y36: 55794000 | Z36: 1.662096e+09 | AA36: 3.88556e+08 | AB36: 104808000 | AC36: 99863000 | AD36: 8384000 | AE36: 19632000 | AF36: 27409000 | AG36: 15164000 | AH36: 1012000 | AI36: =SUM(C36:AH36) -> 6.884942e+10
B37: IMP | C37: 441478000 | D37: 102246000 | E37: 2301000 | F37: 145696000 | G37: 1576951000 | H37: 414921000 | I37: 2274141000 | J37: 170619000 | K37: 2546616000 | L37: 5683876000 | M37: 431667000 | N37: 10135073000 | O37: 8420656000 | P37: 375993000 | Q37: 1789351000 | R37: 344422000 | S37: 2945274000 | T37: 2938949000 | U37: 2265872000 | V37: 465146000 | W37: 1339850000 | X37: 634249000 | Y37: 299403000 | Z37: 1546505000 | AA37: 84090000 | AB37: 143733000 | AC37: 949775000 | AD37: 352203000 | AE37: 1181898000 | AF37: 245256000 | AG37: 52272000 | AH37: 230171000 | AI37: =SUM(C37:AH37) -> 50530653000 | AJ37: (with ind 18)
J38: Note additiona industry
A40: Final demand shares (elementwise ratio between f_imp and f_tot)
B41: Sector | C41: f_HH_imp/f_HH_tot | D41: f_gov_imp/f_gov_tot | E41: f_gfcf_imp/f_gfcf_tot | G41: f_hh_tot | J41: HH IMP | K41: GOV IMP | L41: GFCF IMP | O41: EXP | T41: P3/S14 Final consumption expenditure by households on imports in 2010 (total)
A42: A1 | B42: 1 | C42: =J42/inputoutput!#REF! -> #REF! | D42: =K42/inputoutput!#REF! -> #REF! | E42: =L42/inputoutput!#REF! -> #REF! | G42: =J42/C42 -> #REF! | J42: 146524000 | K42: 4000 | L42: 66000 | N42: A1 | O42: 4.74186e+08 | T42: 11213615000
A43: A2 | B43: 2 | C43: =J43/inputoutput!#REF! -> #REF! | D43: =K43/inputoutput!#REF! -> #REF! | E43: =L43/inputoutput!#REF! -> #REF! | G43: =J43/C43 -> #REF! | J43: 645000 | K43: 0 | L43: 52000 | N43: A2 | O43: 44825000
A44: A3 | B44: 3 | C44: =J44/inputoutput!#REF! -> #REF! | D44: =K44/inputoutput!#REF! -> #REF! | E44: =L44/inputoutput!#REF! -> #REF! | G44: =J44/C44 -> #REF! | J44: 419000 | K44: 0 | L44: 0 | N44: A3 | O44: 17441000
A45: B | B45: 4 | C45: =J45/inputoutput!#REF! -> #REF! | D45: =K45/inputoutput!#REF! -> #REF! | E45: =L45/inputoutput!#REF! -> #REF! | G45: =J45/C45 -> #REF! | J45: 32000 | K45: 0 | L45: 11000 | N45: B | O45: 383252000
A46: C10_12 | B46: 5 | C46: =J46/inputoutput!#REF! -> #REF! | D46: =K46/inputoutput!#REF! -> #REF! | E46: =L46/inputoutput!#REF! -> #REF! | G46: =J46/C46 -> #REF! | J46: 293426000 | K46: 69000 | L46: 115000 | N46: C10_12 | O46: 1408114000
A47: C13_15 | B47: 6 | C47: =J47/inputoutput!#REF! -> #REF! | D47: =K47/inputoutput!#REF! -> #REF! | E47: =L47/inputoutput!#REF! -> #REF! | G47: =J47/C47 -> #REF! | J47: 127857000 | K47: 12000 | L47: 215000 | N47: C13_15 | O47: 607495000
A48: C16_17 | B48: 7 | C48: =J48/inputoutput!#REF! -> #REF! | D48: =K48/inputoutput!#REF! -> #REF! | E48: =L48/inputoutput!#REF! -> #REF! | G48: =J48/C48 -> #REF! | J48: 7155000 | K48: 9000 | L48: 480000 | N48: C16_17 | O48: 10980171000
A49: C20_22 | B49: 8 | C49: =J49/inputoutput!#REF! -> #REF! | D49: =K49/inputoutput!#REF! -> #REF! | E49: =L49/inputoutput!#REF! -> #REF! | G49: =J49/C49 -> #REF! | J49: 48325000 | K49: 20296000 | L49: 1237000 | N49: C20_22 | O49: 5.747783e+09
A50: C19 | B50: 9 | C50: =J50/inputoutput!#REF! -> #REF! | D50: =K50/inputoutput!#REF! -> #REF! | E50: =L50/inputoutput!#REF! -> #REF! | G50: =J50/C50 -> #REF! | J50: 9405000 | K50: 35000 | L50: 25000 | N50: C19 | O50: 3620733000
A51: C23 | B51: 10 | C51: =J51/inputoutput!#REF! -> #REF! | D51: =K51/inputoutput!#REF! -> #REF! | E51: =L51/inputoutput!#REF! -> #REF! | G51: =J51/C51 -> #REF! | J51: 3115000 | K51: 6000 | L51: 89000 | N51: C23 | O51: 6.34111e+08
A52: C24_33 | B52: 11 | C52: =J52/inputoutput!#REF! -> #REF! | D52: =K52/inputoutput!#REF! -> #REF! | E52: =L52/inputoutput!#REF! -> #REF! | G52: =J52/C52 -> #REF! | J52: 53422000 | K52: 44000 | L52: 50818000 | N52: C24_33 | O52: 1.8500951e+10
A53: C26_27 | B53: 12 | C53: =J53/inputoutput!#REF! -> #REF! | D53: =K53/inputoutput!#REF! -> #REF! | E53: =L53/inputoutput!#REF! -> #REF! | G53: =J53/C53 -> #REF! | J53: 22842000 | K53: 3000 | L53: 7490000 | N53: C26_27 | O53: 14182868000
A54: C31_32 | B54: 13 | C54: =J54/inputoutput!#REF! -> #REF! | D54: =K54/inputoutput!#REF! -> #REF! | E54: =L54/inputoutput!#REF! -> #REF! | G54: =J54/C54 -> #REF! | J54: 54821000 | K54: 37000 | L54: 8606000 | N54: C31_32 | O54: 503411000
... A72: ST | B72: 31 | C72: =J72/inputoutput!#REF! -> #REF! | D72: =K72/inputoutput!#REF! -> #REF! | E72: =L72/inputoutput!#REF! -> #REF! | G72: =J72/C72 -> #REF! | J72: 3329000 | K72: 84000 | L72: 224000 | N72: ST | O72: 1012000
I73: TOT | J73: =SUM(J42:J72) -> 1549250000 | K73: =SUM(K42:K72) -> 27182000 | L73: =SUM(L42:L72) -> 179429000 | N73: TOT | O73: =SUM(O42:O72) -> 6.884942e+10 | P73: TOT
A75: Intermediate trade ratios (elementwise ratio between Z_imp and Z_dom)
B76: A1 | C76: A2 | D76: A3 | E76: B | F76: C10_12 | G76: C13_15 | H76: C16_17 | I76: C20_22 | J76: C19 | K76: C23 | L76: C24_33 | M76: C26_27 | N76: C31_32 | O76: D | P76: E | Q76: F | R76: G | S76: H | T76: I | U76: J | V76: K | W76: L | X76: M_N | Y76: M_N_72 | Z76: M_N_73 | AA76: O | AB76: P | AC76: Q | AD76: R | AE76: S95 | AF76: ST
A77: A1 | B77: =IF(inputoutput!C14=0, 0, C2/inputoutput!C14) -> #VALUE! | C77: =IF(inputoutput!D14=0, 0, D2/inputoutput!D14) -> 0 | D77: =IF(inputoutput!E14=0, 0, E2/inputoutput!E14) -> 0 | E77: =IF(inputoutput!F14=0, 0, F2/inputoutput!F14) -> 0 | F77: =IF(inputoutput!G14=0, 0, G2/inputoutput!G14) -> 0.031157318 | G77: =IF(inputoutput!H14=0, 0, H2/inputoutput!H14) -> 0 | H77: =IF(inputoutput!I14=0, 0, I2/inputoutput!I14) -> 0 | I77: =IF(inputoutput!J14=0, 0, J2/inputoutput!J14) -> 0 | ... V77: =IF(inputoutput!W14=0, 0, W2/inputoutput!W14) -> 0 | W77: =IF(inputoutput!#REF!=0, 0, X2/inputoutput!#REF!) -> #REF! | X77: =IF(inputoutput!#REF!=0, 0, Y2/inputoutput!#REF!) -> #REF! | Y77: =IF(inputoutput!#REF!=0, 0, Z2/inputoutput!#REF!) -> #REF! | Z77: =IF(inputoutput!#REF!=0, 0, AA2/inputoutput!#REF!) -> #REF! | AA77: =IF(inputoutput!#REF!=0, 0, AB2/inputoutput!#REF!) -> #REF! | AB77: =IF(inputoutput!#REF!=0, 0, AC2/inputoutput!#REF!) -> #REF! | AC77: =IF(inputoutput!#REF!=0, 0, AD2/inputoutput!#REF!) -> #REF! | AD77: =IF(inputoutput!#REF!=0, 0, AE2/inputoutput!#REF!) -> #REF! | ... AF77: =IF(inputoutput!#REF!=0, 0, AG2/inputoutput!#REF!) -> #REF!
A78: A2 | B78: =IF(inputoutput!C15=0, 0, C3/inputoutput!C15) -> #VALUE! | C78: =IF(inputoutput!D15=0, 0, D3/inputoutput!D15) -> 3.9105902e-05 | D78: =IF(inputoutput!E15=0, 0, E3/inputoutput!E15) -> 0 | E78: =IF(inputoutput!F15=0, 0, F3/inputoutput!F15) -> 0 | F78: =IF(inputoutput!G15=0, 0, G3/inputoutput!G15) -> 0.09816995 | G78: =IF(inputoutput!H15=0, 0, H3/inputoutput!H15) -> 0 | H78: =IF(inputoutput!I15=0, 0, I3/inputoutput!I15) -> 0 | I78: =IF(inputoutput!J15=0, 0, J3/inputoutput!J15) -> 0 | ... V78: =IF(inputoutput!W15=0, 0, W3/inputoutput!W15) -> 0 | W78: =IF(inputoutput!#REF!=0, 0, X3/inputoutput!#REF!) -> #REF! | X78: =IF(inputoutput!#REF!=0, 0, Y3/inputoutput!#REF!) -> #REF! | Y78: =IF(inputoutput!#REF!=0, 0, Z3/inputoutput!#REF!) -> #REF! | Z78: =IF(inputoutput!#REF!=0, 0, AA3/inputoutput!#REF!) -> #REF! | AA78: =IF(inputoutput!#REF!=0, 0, AB3/inputoutput!#REF!) -> #REF! | AB78: =IF(inputoutput!#REF!=0, 0, AC3/inputoutput!#REF!) -> #REF! | AC78: =IF(inputoutput!#REF!=0, 0, AD3/inputoutput!#REF!) -> #REF! | AD78: =IF(inputoutput!#REF!=0, 0, AE3/inputoutput!#REF!) -> #REF! | ... AF78: =IF(inputoutput!#REF!=0, 0, AG3/inputoutput!#REF!) -> #REF!
A79: A3 | B79: =IF(inputoutput!C16=0, 0, C4/inputoutput!C16) -> #VALUE! | C79: =IF(inputoutput!D16=0, 0, D4/inputoutput!D16) -> 1.6047376e-06 | D79: =IF(inputoutput!E16=0, 0, E4/inputoutput!E16) -> 7.1362215e-05 | E79: =IF(inputoutput!F16=0, 0, F4/inputoutput!F16) -> 0 | F79: =IF(inputoutput!G16=0, 0, G4/inputoutput!G16) -> 0.0032180089 | G79: =IF(inputoutput!H16=0, 0, H4/inputoutput!H16) -> 0 | H79: =IF(inputoutput!I16=0, 0, I4/inputoutput!I16) -> 0 | I79: =IF(inputoutput!J16=0, 0, J4/inputoutput!J16) -> 0 | ... V79: =IF(inputoutput!W16=0, 0, W4/inputoutput!W16) -> 0 | W79: =IF(inputoutput!#REF!=0, 0, X4/inputoutput!#REF!) -> #REF! | X79: =IF(inputoutput!#REF!=0, 0, Y4/inputoutput!#REF!) -> #REF! | Y79: =IF(inputoutput!#REF!=0, 0, Z4/inputoutput!#REF!) -> #REF! | Z79: =IF(inputoutput!#REF!=0, 0, AA4/inputoutput!#REF!) -> #REF! | AA79: =IF(inputoutput!#REF!=0, 0, AB4/inputoutput!#REF!) -> #REF! | AB79: =IF(inputoutput!#REF!=0, 0, AC4/inputoutput!#REF!) -> #REF! | AC79: =IF(inputoutput!#REF!=0, 0, AD4/inputoutput!#REF!) -> #REF! | AD79: =IF(inputoutput!#REF!=0, 0, AE4/inputoutput!#REF!) -> #REF! | ... AF79: =IF(inputoutput!#REF!=0, 0, AG4/inputoutput!#REF!) -> #REF!
...

Sheet prices
B1: Initial inflation rate (2010) | C1: 1.2
X6: QUAIDS
C7: Purchasing vs basic prices | Y7: alpha | Z7: beta | AA7: lambda | AB7: gamma
D8: %m | E8: ttm shares | F8: %t | J8: NET PROFITS | L8: Profit share | M8: Mark up | O8: ROUNDED | Y8: constant | Z8: logx | AA8: logx2 | AB8: A | AC8: B | AD8: C | AE8: C19 | AF8: C29 | AG8: D1 | AH8: D2 | AI8: D3 | AJ8: E | AK8: F | AL8: G | AM8: H | AN8: I | AO8: J_R_S | AP8: K | AQ8: L | AR8: H_M_N | AS8: O | AT8: P | AU8: Q | AV8: T
C9: A | D9: 1.3549232 | E9: 0 | F9: 0.055874184 | I9: A | J9: 12166 | L9: 0.42525971 | M9: 0.73991631 | N9: 0.73991631 | O9: 0.7399 | P9: 0.7399 | X9: A | Y9: -0.064848896 | Z9: 0.04228537 | AA9: -0.0035720667 | AB9: -0.0034549199 | AC9: 0.0024172738 | AD9: -0.016899921 | AE9: 0.00077302585 | AF9: -0.0012589731 | AG9: 0.0018866715 | AH9: 0.0022288912 | AI9: 5.605964e-06 | AJ9: 0.00098152814 | AK9: 0.0018044457 | AL9: -0.00076693067 | AM9: -5.5145869e-05 | AN9: -0.0084944965 | AO9: -0.00097551888 | AP9: 0.0011532421 | AQ9: 0.022035818 | AR9: -0.00036466417 | AS9: 4.8032443e-06 | AT9: -0.00016950876 | AU9: -0.0020173931 | AV9: 0.0011661747
C10: B | D10: 0.25883976 | E10: 0 | F10: 0.42863956 | I10: B | J10: 858.3 | L10: 0.18988938 | M10: 0.23439932 | N10: 0.23439932 | O10: 0.2344 | P10: 0.2344 | X10: B | Y10: 0.10395555 | Z10: -0.015242335 | AA10: 0.00033017896 | AB10: 0.0024172738 | AC10: -0.0025850906 | AD10: 0.013243738 | AE10: -0.00066603033 | AF10: 0.00074848713 | AG10: -0.0013282121 | AH10: -0.001569134 | AI10: -3.9467466e-06 | AJ10: -0.0034167647 | AK10: -0.0010597108 | AL10: 0.00045525572 | AM10: 0.00053070702 | AN10: 0.0040406308 | AO10: 0.001389119 | AP10: 0.00034908945 | AQ10: -0.012965444 | AR10: -0.0002122864 | AS10: -4.0875062e-05 | AT10: -0.00022524989 | AU10: 0.0014441282 | AV10: -0.0005456821
C11: C | D11: 0.89949778 | E11: 0 | F11: 0.15563465 | I11: C | J11: 38745.8 | L11: 0.18474917 | M11: 0.22661636 | N11: 0.22661636 | O11: 0.2266 | P11: 0.2266 | X11: C | Y11: -0.51751324 | Z11: 0.21334305 | AA11: -0.013524173 | AB11: -0.016899921 | AC11: 0.013243738 | AD11: -0.090413455 | AE11: 0.0048717493 | AF11: -0.0074036107 | AG11: 0.011404001 | AH11: 0.01347255 | AI11: 3.3885074e-05 | AJ11: 0.002202875 | AK11: 0.010285618 | AL11: -0.0044963226 | AM11: -0.00023776273 | AN11: -0.044247913 | AO11: -0.0090049038 | AP11: 0.0051587017 | AQ11: 0.12572778 | AR11: -0.0032140161 | AS11: -7.0918932e-05 | AT11: -0.0014649049 | AU11: -0.012339225 | AV11: 0.003392106
C12: C19 | D12: 0.23587856 | E12: 0 | F12: 0.84077569 | I12: C19 | J12: -1093.4 | L12: -0.43723757 | M12: -0.30422081 | N12: -0.30422081 | O12: -0.3042 | P12: -0.3042 | X12: C19 | Y12: 0.061805927 | Z12: -0.010194476 | AA12: 0.0010291914 | AB12: 0.00077302585 | AC12: -0.00066603033 | AD12: 0.0048717493 | AE12: 0.0038652979 | AF12: 0.0045670039 | AG12: -0.00016051399 | AH12: -0.00018962931 | AI12: -4.7698728e-07 | AJ12: -0.00082492652 | AK12: -0.0012798532 | AL12: 0.0027931938 | AM12: -0.0010412591 | AN12: 0.0012850754 | AO12: -0.00077345163 | AP12: -5.9337368e-05 | AQ12: -0.015767619 | AR12: 0.0012423208 | AS12: 4.3555549e-05 | AT12: 0.00063004942 | AU12: 0.0012763646 | AV12: -0.00058453382
C13: C29 | D13: 0.30455052 | E13: 0 | F13: 0.12853328 | I13: C29_30 | J13: -275.9 | L13: -0.016179351 | M13: -0.015921747 | N13: -0.015921747 | O13: -0.0159 | P13: -0.0159 | X13: C29 | Y13: -0.023802651 | Z13: 0.003653335 | AA13: 0.00070178345 | AB13: -0.0012589731 | AC13: 0.00074848713 | AD13: -0.0074036107 | AE13: 0.0045670039 | AF13: 0.0043061961 | AG13: 0.00077780732 | AH13: 0.00091889228 | AI13: 2.3111283e-06 | AJ13: 0.00021673048 | AK13: -0.00028122987 | AL13: 0.0026320383 | AM13: -0.00061067686 | AN13: -0.00021882652 | AO13: -0.002114048 | AP13: -0.00044731989 | AQ13: -0.003481305 | AR13: 0.0013090447 | AS13: 6.4031805e-06 | AT13: 0.00041422718 | AU13: 0.00027670685 | AV13: -0.00035985849
C14: D1 | D14: 0.00019206511 | E14: 0 | F14: 0.22739896 | I14: D | J14: 4527.4 | L14: 0.18606314 | M14: 0.22859653 | N14: 0.22859653 | O14: 0.2286 | P14: 0.2286 | Q14: repeat the same value D1. D2, D3 | X14: D1 | Y14: 0.083043649 | Z14: -0.013560398 | AA14: 0.00043808494 | AB14: 0.0018866715 | AC14: -0.0013282121 | AD14: 0.011404001 | AE14: -0.00016051399 | AF14: 0.00077780732 | AG14: -0.00085218077 | AH14: -0.0010067562 | AI14: -2.5321621e-06 | AJ14: -0.0010035414 | AK14: -0.0010355145 | AL14: 0.00047721671 | AM14: -0.00050978803 | AN14: 0.0015257487 | AO14: 0.0010792583 | AP14: 0.00033876654 | AQ14: -0.012741511 | AR14: 9.2713209e-05 | AS14: 3.7909277e-05 | AT14: 0.00026509266 | AU14: 0.0010294582 | AV14: -0.00027408775
C15: D2 | D15: 0.00019206511 | E15: 0 | F15: 0.22739896 | I15: E | J15: 323.7 | L15: 0.025606746 | M15: 0.026279683 | N15: 0.026279683 | O15: 0.0263 | P15: 0.0263 | X15: D2 | Y15: 0.098106776 | Z15: -0.016020093 | AA15: 0.00051754832 | AB15: 0.0022288912 | AC15: -0.001569134 | AD15: 0.01347255 | AE15: -0.00018962931 | AF15: 0.00091889228 | AG15: -0.0010067562 | AH15: -0.0011893697 | AI15: -2.991466e-06 | AJ15: -0.0011855718 | AK15: -0.0012233445 | AL15: 0.00056377813 | AM15: -0.0006022575 | AN15: 0.0018025013 | AO15: 0.0012750229 | AP15: 0.00040021474 | AQ15: -0.015052669 | AR15: 0.00010953028 | AS15: 4.4785567e-05 | AT15: 0.00031317731 | AU15: 0.0012161896 | AV15: -0.000323804
C16: D3 | D16: 0.00019206511 | E16: 0 | F16: 0.22739896 | I16: F | J16: 33520.6 | L16: 0.41104152 | M16: 0.69791255 | N16: 0.69791255 | O16: 0.6979 | P16: 0.6979 | X16: D3 | Y16: 0.0002467504 | Z16: -4.0292078e-05 | AA16: 1.3016396e-06 | AB16: 5.605964e-06 | AC16: -3.9467466e-06 | AD16: 3.3885074e-05 | AE16: -4.7698728e-07 | AF16: 2.3111283e-06 | AG16: -2.5321621e-06 | AH16: -2.991466e-06 | AI16: -7.5240431e-09 | AJ16: -2.9822893e-06 | AK16: -3.0768308e-06 | AL16: 1.4179713e-06 | AM16: -1.5145651e-06 | AN16: 4.5338296e-06 | AO16: 3.2068442e-06 | AP16: 1.0065961e-06 | AQ16: -3.7858922e-05 | AR16: 2.7542636e-07 | AS16: 1.1262695e-07 | AT16: 7.8759077e-07 | AU16: 3.0589e-06 | AV16: -8.1444318e-07
C17: E | D17: 0 | E17: 0 | F17: 0.086380336 | I17: G | J17: 75690.2 | L17: 0.464843 | M17: 0.86861053 | N17: 0.86861053 | O17: 0.8686 | P17: 0.8686 | X17: E | Y17: 0.018209119 | Z17: 0.0036244411 | AA17: -0.00085898339 | AB17: 0.00098152814 | AC17: -0.0034167647 | AD17: 0.002202875 | AE17: -0.00082492652 | AF17: 0.00021673048 | AG17: -0.0010035414 | AH17: -0.0011855718 | AI17: -2.9822893e-06 | AJ17: -0.0075420495 | AK17: 0.00025425857 | AL17: 0.00012082817 | AM17: 0.0030224833 | AN17: 0.005766964 | AO17: 0.00035571274 | AP17: 0.00017892013 | AQ17: 0.0033130324 | AR17: -0.00092232133 | AS17: -0.00023205649 | AT17: -0.0014337216 | AU17: 0.00083909704 | AV17: -0.00068850088
C18: F | D18: 0 | E18: 0 | F18: 0.095396654 | I18: H49_51 | J18: 16074.7 | L18: 0.33700499 | M18: 0.50830698 | N18: 0.50830698 | O18: 0.5083 | P18: 0.5083 | X18: F | Y18: 0.11554528 | Z18: -0.020706802 | AA18: 0.0010028413 | AB18: 0.0018044457 | AC18: -0.0010597108 | AD18: 0.010285618 | AE18: -0.0012798532 | AF18: -0.00028122987 | AG18: -0.0010355145 | AH18: -0.0012233445 | AI18: -3.0768308e-06 | AJ18: 0.00025425857 | AK18: -0.00099321259 | AL18: -0.00017290341 | AM18: 5.0164538e-05 | AN18: 0.0035531246 | AO18: 0.0015767941 | AP18: -0.00029295324 | AQ18: -0.012161829 | AR18: 5.9112008e-05 | AS18: 4.8779578e-06 | AT18: 3.3876606e-05 | AU18: 0.0011726295 | AV18: -0.000291274
C19: G | D19: 0 | E19: 0.92758928 | F19: 0.12050178 | I19: M+N+U | J19: 71055.2 | L19: 0.41970366 | M19: 0.72325746 | N19: 0.72325746 | O19: 0.7233 | P19: 0.7233 | X19: G | Y19: -0.014465698 | Z19: 0.0022924618 | AA19: 0.00041143783 | AB19: -0.00076693067 | AC19: 0.00045525572 | AD19: -0.0044963226 | AE19: 0.0027931938 | AF19: 0.0026320383 | AG19: 0.00047721671 | AH19: 0.00056377813 | AI19: 1.4179713e-06 | AJ19: 0.00012082817 | AK19: -0.00017290341 | AL19: 0.0016087227 | AM19: -0.00037038066 | AN19: -0.00016171294 | AO19: -0.0012823429 | AP19: -0.0002752909 | AQ19: -0.0021411103 | AR19: 0.00079807247 | AS19: 4.0433588e-06 | AT19: 0.00025414635 | AU19: 0.00017452357 | AV19: -0.00021624286
C20: H | D20: 0 | E20: 0.072410778 | F20: -0.2841447 | I20: I | J20: 22214.9 | L20: 0.42256707 | M20: 0.73180285 | N20: 0.73180285 | O20: 0.7318 | P20: 0.7318 | X20: H | Y20: -0.0074816122 | Z20: -0.0038831772 | AA20: 0.0005360698 | AB20: -5.5145869e-05 | AC20: 0.00053070702 | AD20: -0.00023776273 | AE20: -0.0010412591 | AF20: -0.00061067686 | AG20: -0.00050978803 | AH20: -0.0006022575 | AI20: -1.5145651e-06 | AJ20: 0.0030224833 | AK20: 5.0164538e-05 | AL20: -0.00037038066 | AM20: -0.0086434843 | AN20: 0.0033009382 | AO20: 0.0016884502 | AP20: -0.00032260884 | AQ20: 0.00071326054 | AR20: 0.00038037934 | AS20: 9.8902509e-05 | AT20: 0.00059217232 | AU20: 0.0013648171 | AV20: 0.00065262339
C21: I | D21: 0 | E21: 0 | F21: 0.056422516 | I21: J+R+S | J21: 44111.3 | L21: 0.42900602 | M21: 0.75133195 | N21: 0.75133195 | O21: 0.7513 | P21: 0.7513 | X21: I | Y21: -0.15344782 | Z21: 0.043606154 | AA21: -0.0018047008 | AB21: -0.0084944965 | AC21: 0.0040406308 | AD21: -0.044247913 | AE21: 0.0012850754 | AF21: -0.00021882652 | AG21: 0.0015257487 | AH21: 0.0018025013 | AI21: 4.5338296e-06 | AJ21: 0.005766964 | AK21: 0.0035531246 | AL21: -0.00016171294 | AM21: 0.0033009382 | AN21: -0.017076946 | AO21: -0.0013801909 | AP21: 0.00053774393 | AQ21: 0.043384271 | AR21: 0.0012320288 | AS21: 0.00032934975 | AT21: 0.0019665156 | AU21: 0.00054088996 | AV21: 0.0023097613
C22: J_R_S | D22: 0.064394869 | E22: 0 | F22: 0.22249796 | I22: K | J22: 30291.4 | L22: 0.40023149 | M22: 0.66730993 | N22: 0.66730993 | O22: 0.6673 | P22: 0.6673 | X22: J_R_S | Y22: -0.064586261 | Z22: 0.017245923 | AA22: 0.00020078734 | AB22: -0.00097551888 | AC22: 0.001389119 | AD22: -0.0090049038 | AE22: -0.00077345163 | AF22: -0.002114048 | AG22: 0.0010792583 | AH22: 0.0012750229 | AI22: 3.2068442e-06 | AJ22: 0.00035571274 | AK22: 0.0015767941 | AL22: -0.0012823429 | AM22: 0.0016884502 | AN22: -0.0013801909 | AO22: -0.0084765586 | AP22: -0.00032279118 | AQ22: 0.019430209 | AR22: -0.0010561577 | AS22: -3.3471069e-05 | AT22: -0.00034167624 | AU22: -0.0012701759 | AV22: 0.00023353801
C23: K | D23: 0 | E23: 0 | F23: 0.14059671 | I23: L | J23: 116564.2 | L23: 0.63143862 | M23: 1.7132522 | N23: 1.7132522 | O23: 1.7133 | P23: 1.7133 | X23: K | Y23: 0.020254662 | Z23: -0.0063479894 | AA23: 0.0010928222 | AB23: 0.0011532421 | AC23: 0.00034908945 | AD23: 0.0051587017 | AE23: -5.9337368e-05 | AF23: -0.00044731989 | AG23: 0.00033876654 | AH23: 0.00040021474 | AI23: 1.0065961e-06 | AJ23: 0.00017892013 | AK23: -0.00029295324 | AL23: -0.0002752909 | AM23: -0.00032260884 | AN23: 0.00053774393 | AO23: -0.00032279118 | AP23: -0.0023977257 | AQ23: -0.0036046832 | AR23: -0.00026067626 | AS23: -5.1430037e-05 | AT23: -0.00014163583 | AU23: 0.00037881375 | AV23: -0.0003200385
C24: L | D24: 0 | E24: 0 | F24: 0.0016907695 | I24: O | J24: 1234 | L24: 0.011926508 | M24: 0.012070466 | N24: 0.012070466 | O24: 0.0121 | P24: 0.0121 | X24: L | Y24: 1.422317 | Z24: -0.25444291 | AA24: 0.01233328 | AB24: 0.022035818 | AC24: -0.012965444 | AD24: 0.12572778 | AE24: -0.015767619 | AF24: -0.003481305 | AG24: -0.012741511 | AH24: -0.015052669 | AI24: -3.7858922e-05 | AJ24: 0.0033130324 | AK24: -0.012161829 | AL24: -0.0021411103 | AM24: 0.00071326054 | AN24: 0.043384271 | AO24: 0.019430209 | AP24: -0.0036046832 | AQ24: -0.14892437 | AR24: 0.00076560838 | AS24: 6.9785473e-05 | AT24: 0.00047542033 | AU24: 0.01449346 | AV24: -0.0035302403
C25: H_M_N | D25: 0.00011800368 | E25: 0 | F25: 0.13905726 | I25: P | J25: 2951 | L25: 0.045631033 | M25: 0.04781278 | N25: 0.04781278 | O25: 0.0478 | P25: 0.0478 | X25: H_M_N | Y25: -0.0084291149 | Z25: 0.0010968915 | AA25: 0.0005179038 | AB25: -0.00036466417 | AC25: -0.0002122864 | AD25: -0.0032140161 | AE25: 0.0012423208 | AF25: 0.0013090447 | AG25: 9.2713209e-05 | AH25: 0.00010953028 | AI25: 2.7542636e-07 | AJ25: -0.00092232133 | AK25: 5.9112008e-05 | AL25: 0.00079807247 | AM25: 0.00038037934 | AN25: 0.0012320288 | AO25: -0.0010561577 | AP25: -0.00026067626 | AQ25: 0.00076560838 | AR25: 0.00026991555 | AS25: -3.9994633e-05 | AT25: -0.0001224267 | AU25: 0.00022655537 | AV25: -0.00029301233
C26: O | D26: 0 | E26: 0 | F26: 0 | I26: Q | J26: 18873 | L26: 0.21729444 | M26: 0.27761965 | N26: 0.27761965 | O26: 0.2776 | P26: 0.2776 | X26: O | Y26: -0.00076014439 | Z26: -0.000260461 | AA26: 4.570969e-05 | AB26: 4.8032443e-06 | AC26: -4.0875062e-05 | AD26: -7.0918932e-05 | AE26: 4.3555549e-05 | AF26: 6.4031805e-06 | AG26: 3.7909277e-05 | AH26: 4.4785567e-05 | AI26: 1.1262695e-07 | AJ26: -0.00023205649 | AK26: 4.8779578e-06 | AL26: 4.0433588e-06 | AM26: 9.8902509e-05 | AN26: 0.00032934975 | AO26: -3.3471069e-05 | AP26: -5.1430037e-05 | AQ26: 6.9785473e-05 | AR26: -3.9994633e-05 | AS26: -2.1819564e-05 | AT26: -0.00012971946 | AU26: -8.3759274e-05 | AV26: 5.9514745e-05
C27: P | D27: 0 | E27: 0 | F27: 0.012684032 | I27: T | J27: 0 | L27: 0 | M27: 0 | N27: 0 | O27: 0 | P27: 0 | X27: P | Y27: -0.008320972 | Z27: -0.00075824646 | AA27: 0.00023861018 | AB27: -0.00016950876 | AC27: -0.00022524989 | AD27: -0.0014649049 | AE27: 0.00063004942 | AF27: 0.00041422718 | AG27: 0.00026509266 | AH27: 0.00031317731 | AI27: 7.8759077e-07 | AJ27: -0.0014337216 | AK27: 3.3876606e-05 | AL27: 0.00025414635 | AM27: 0.00059217232 | AN27: 0.0019665156 | AO27: -0.00034167624 | AP27: -0.00014163583 | AQ27: 0.00047542033 | AR27: -0.0001224267 | AS27: -0.00012971946 | AT27: -0.00075632874 | AU27: -0.00052846647 | AV27: 0.00036816466
C28: Q | D28: 0 | E28: 0 | F28: 0.071849625 | X28: Q | Y28: -0.068823204 | Z28: 0.02105857 | AA28: -0.00074932519 | AB28: -0.0020173931 | AC28: 0.0014441282 | AD28: -0.012339225 | AE28: 0.0012763646 | AF28: 0.00027670685 | AG28: 0.0010294582 | AH28: 0.0012161896 | AI28: 3.0589e-06 | AJ28: 0.00083909704 | AK28: 0.0011726295 | AL28: 0.00017452357 | AM28: 0.0013648171 | AN28: 0.00054088996 | AO28: -0.0012701759 | AP28: 0.00037881375 | AQ28: 0.01449346 | AR28: 0.00022655537 | AS28: -8.3759274e-05 | AT28: -0.00052846647 | AU28: -0.0081862522 | AV28: -1.1421068e-05
C29: T | D29: 0 | E29: 0 | F29: 0 | X29: T | Y29: 0.0089949638 | Z29: -0.0067490145 | AA29: 0.001111679 | AB29: 0.0011661747 | AC29: -0.0005456821 | AD29: 0.003392106 | AE29: -0.00058453382 | AF29: -0.00035985849 | AG29: -0.00027408775 | AH29: -0.000323804 | AI29: -8.1444318e-07 | AJ29: -0.00068850088 | AK29: -0.000291274 | AL29: -0.00021624286 | AM29: 0.00065262339 | AN29: 0.0023097613 | AO29: 0.00023353801 | AP29: -0.0003200385 | AQ29: -0.0035302403 | AR29: -0.00029301233 | AS29: 5.9514745e-05 | AT29: 0.00036816466 | AU29: -1.1421068e-05 | AV29: -0.00074237134
B33: Dataset: 6A. Value added and its components by activity, ISIC rev4 | C33: NET OPERATING SURPLUS | O33: CORRESPONDANCE
B34: Country | G34: Italy | O34: Old Eurogreen (till July 23) | R34: New Eurogreen (after July 23)
B35: Transaction | G35: Net operating surplus and net mixed income | O35: Million euro (2010) ITALY - TOTAL
B36: Measure | G36: Current prices | O36: A | P36: V01 | Q36: 1 | R36: A | S36: V01
B37: Unit | G37: Euro, Millions | P37: V02 | Q37: 2 | S37: V02
B38: Year | G38: 2010 | H38: 2011 | I38: 2012 | J38: 2013 | K38: 2014 | L38: 2015 | P38: V03 | Q38: 3 | S38: V03
B39: Activity | F39: i | O39: B | P39: VB | Q39: 4 | R39: B | S39: VB
B40: VTOT: Total activity | G40: 487832.6 | H40: 501130.3 | I40: 466755.7 | J40: 471861.1 | K40: 478427.9 | L40: 484861.3 | O40: C | P40: V10_12 | Q40: 5 | R40: C | S40: V10_12
B41: VTOT: Total activity | C41: VA0: Agriculture, forestry and fishing | G41: 12166 | H41: 14753.4 | I41: 15722.5 | J41: 19351.2 | K41: 17746.6 | L41: 16968 | P41: V13_15 | Q41: 6 | S41: V13_15
C42: VA0: Agriculture, forestry and fishing | D42: V01: Crop and animal production, hunting and related service activities | F42: V01 | G42: 10884.1 | H42: 13612.2 | I42: 14594.2 | J42: 18204.9 | K42: 16700 | L42: 15824.8 | P42: V16 | Q42: 7 | S42: V16
D43: V02: Forestry and logging | F43: V02 | G43: 642.2 | H43: 573.3 | I43: 709.6 | J43: 872.3 | K43: 799.5 | L43: 813.8 | P43: V17 | Q43: 8 | S43: V17
D44: V03: Fishing and aquaculture | F44: V03 | G44: 639.7 | H44: 568 | I44: 418.6 | J44: 273.9 | K44: 247.1 | L44: 329.3 | P44: V18 | Q44: 9 | S44: V18
C45: VB: Mining and quarrying | F45: VB | G45: 858.3 | H45: 1578.4 | I45: 2933.8 | J45: 2699.7 | K45: 1757.2 | L45: 492.7 | O45: C19 | P45: V19 | Q45: 10 | R45: C19 | S45: V19
C46: VC: Manufacturing | G46: 37376.5 | H46: 37110.7 | I46: 28181.8 | J46: 28971.5 | K46: 31159 | L46: 38395 | O46: C | P46: V20 | Q46: 11 | R46: C | S46: V20
C47: VC: Manufacturing | D47: V10_12: Manufacture of food products, beverages and tobacco products | F47: V10_12 | G47: 6077 | H47: 5047.9 | I47: 4325.4 | J47: 4302 | K47: 4707.5 | L47: 6016 | P47: V21 | Q47: 12 | S47: V21
...

Sheet consumption
A1: Bridge matrix to convert elasticities in coicop to elasticities in industries, and to convert consumption per coicop in consumption per industry
B2: CP01 | C2: CP02 | D2: CP03 | E2: CP041_043 | F2: CP044 | G2: CP045 | H2: CP05 | I2: CP06 | J2: CP071_072 | K2: CP073 | L2: CP08 | M2: CP09 | N2: CP10 | O2: CP11 | P2: CP121 | Q2: CP122_127
A3: A | B3: 0.80856339 | C3: 3.6229471e-05 | D3: 0 | E3: 0 | F3: 1.9008405e-08 | G3: 0.01223122 | H3: 4.4159524e-06 | I3: 0.0043145903 | J3: 0 | K3: 0 | L3: 0 | M3: 0.11387252 | N3: 0 | O3: 0.060973436 | P3: 0 | Q3: 4.1784029e-06 | R3: =SUM(B3:Q3) -> 1
A4: B | B4: 0 | C4: 0 | D4: 0 | E4: 0.12287792 | F4: 0.24545902 | G4: 0.55530243 | H4: 0 | I4: 0 | J4: 0 | K4: 0 | L4: 0 | M4: 0.054342633 | N4: 0 | O4: 0 | P4: 0 | Q4: 0.022017994 | R4: =SUM(B4:Q4) -> 1
A5: C | B5: 0.33127068 | C5: 0.1275798 | D5: 0.19176278 | E5: 0.0037296377 | F5: 7.9869189e-07 | G5: 6.216661e-06 | H5: 0.1391398 | I5: 0.037736473 | J5: 0.038648037 | K5: 0 | L5: 0.013298409 | M5: 0.043769555 | N5: 0 | O5: 0.0098082424 | P5: 0 | Q5: 0.063249561 | R5: =SUM(B5:Q5) -> 1
A6: C19 | B6: 0 | C6: 0 | D6: 0 | E6: 0 | F6: 2.0928001e-07 | G6: 0.24011012 | H6: 0.00013796073 | I6: 0 | J6: 0.75975171 | K6: 0 | L6: 0 | M6: 0 | N6: 0 | O6: 0 | P6: 0 | Q6: 0 | R6: =SUM(B6:Q6) -> 1
A7: C29 | B7: 0 | C7: 0 | D7: 0 | E7: 0 | F7: 0 | G7: 0 | H7: 0.00084870699 | I7: 0.00042678429 | J7: 0.97684942 | K7: 0 | L7: 0 | M7: 0.015649849 | N7: 0 | O7: 0 | P7: 0 | Q7: 0.0062252375 | R7: =SUM(B7:Q7) -> 1
A8: D1 | B8: 0 | C8: 0 | D8: 0 | E8: 0 | F8: 0 | G8: 1 | H8: 0 | I8: 0 | J8: 0 | K8: 0 | L8: 0 | M8: 0 | N8: 0 | O8: 0 | P8: 0 | Q8: 0 | R8: =SUM(B8:Q8) -> 1
A9: D2 | B9: 0 | C9: 0 | D9: 0 | E9: 0 | F9: 0 | G9: 1 | H9: 0 | I9: 0 | J9: 0 | K9: 0 | L9: 0 | M9: 0 | N9: 0 | O9: 0 | P9: 0 | Q9: 0 | R9: =SUM(B9:Q9) -> 1
A10: D3 | B10: 0 | C10: 0 | D10: 0 | E10: 0 | F10: 2.5062424e-05 | G10: 0.99997494 | H10: 0 | I10: 0 | J10: 0 | K10: 0 | L10: 0 | M10: 0 | N10: 0 | O10: 0 | P10: 0 | Q10: 0 | R10: =SUM(B10:Q10) -> 1
A11: E | B11: 0 | C11: 0 | D11: 0 | E11: 2.2139924e-06 | F11: 0.96973932 | G11: 8.0669478e-06 | H11: 1.932009e-06 | I11: 0 | J11: 6.5533943e-06 | K11: 0 | L11: 0 | M11: 5.9310074e-07 | N11: 0 | O11: 0 | P11: 0 | Q11: 0.030241319 | R11: =SUM(B11:Q11) -> 1
A12: F | B12: 0 | C12: 0 | D12: 0 | E12: 0.99974864 | F12: 5.9143422e-05 | G12: 0.00013380028 | H12: 4.2364606e-05 | I12: 0 | J12: 0 | K12: 0 | L12: 1.6053675e-05 | M12: 0 | N12: 0 | O12: 0 | P12: 0 | Q12: 0 | R12: =SUM(B12:Q12) -> 1
A13: G | B13: 0 | C13: 0 | D13: 0 | E13: 0 | F13: 0 | G13: 0 | H13: 0 | I13: 0 | J13: 0.99999978 | K13: 0 | L13: 0 | M13: 2.1575638e-07 | N13: 0 | O13: 0 | P13: 0 | Q13: 0 | R13: =SUM(B13:Q13) -> 1
A14: H | B14: 0 | C14: 0 | D14: 0 | E14: 0 | F14: 0 | G14: 0 | H14: 0 | I14: 0 | J14: 0.0036617984 | K14: 0.93395673 | L14: 0 | M14: 0.00020210196 | N14: 0 | O14: 0 | P14: 0.062179373 | Q14: 0 | R14: =SUM(B14:Q14) -> 1
... A23: T | B23: 0 | C23: 0 | D23: 0 | E23: 3.0896752e-06 | F23: 0 | G23: 0 | H23: 0.13441556 | I23: 0 | J23: 0 | K23: 0 | L23: 0 | M23: 0 | N23: 0 | O23: 0 | P23: 0.86558135 | Q23: 0 | R23: =SUM(B23:Q23) -> 1
A25: Bridge matrix to convert consumption shares in coicop to consumption shares in industries
B26: CP01 | C26: CP02 | D26: CP03 | E26: CP041_043 | F26: CP044 | G26: CP045 | H26: CP05 | I26: CP06 | J26: CP071_072 | K26: CP073 | L26: CP08 | M26: CP09 | N26: CP10 | O26: CP11 | P26: CP121 | Q26: CP122_127
A27: A | B27: 0.2568889 | C27: 4.0218001e-05 | D27: 0 | E27: 0 | F27: 4.9489568e-08 | G27: 0.014537703 | H27: 3.7787024e-06 | I27: 0.0062472771 | J27: 0 | K27: 0 | L27: 0 | M27: 0.072181148 | N27: 0 | O27: 0.029561788 | P27: 0 | Q27: 2.0633928e-06
A28: B | B28: 0 | C28: 0 | D28: 0 | E28: 0.011796333 | F28: 0.22057574 | G28: 0.22780662 | H28: 0 | I28: 0 | J28: 0 | K28: 0 | L28: 0 | M28: 0.011889301 | N28: 0 | O28: 0 | P28: 0 | Q28: 0.0037528407
A29: C | B29: 0.74311107 | C29: 0.99995368 | D29: 0.95073081 | E29: 0.0073243402 | F29: 1.4682051e-05 | G29: 5.2170219e-05 | H29: 0.84063827 | I29: 0.38579091 | J29: 0.11317985 | K29: 0 | L29: 0.14937066 | M29: 0.1958919 | N29: 0 | O29: 0.033575361 | P29: 0 | Q29: 0.22053047
A30: C19 | B30: 0 | C30: 0 | D30: 0 | E30: 0 | F30: 4.5271504e-07 | G30: 0.23711862 | H30: 9.8085092e-05 | I30: 0 | J30: 0.26182015 | K30: 0 | L30: 0 | M30: 0 | N30: 0 | O30: 0 | P30: 0 | Q30: 0
A31: C29 | B31: 0 | C31: 0 | D31: 0 | E31: 0 | F31: 0 | G31: 0 | H31: 0.00053464478 | I31: 0.0004549345 | J31: 0.29827651 | K31: 0 | L31: 0 | M31: 0.00730305 | N31: 0 | O31: 0 | P31: 0 | Q31: 0.0022631679
A32: D1 | B32: 0 | C32: 0 | D32: 0 | E32: 0 | F32: 0 | G32: 0.23825409 | H32: 0 | I32: 0 | J32: 0 | K32: 0 | L32: 0 | M32: 0 | N32: 0 | O32: 0 | P32: 0 | Q32: 0
A33: D2 | B33: 0 | C33: 0 | D33: 0 | E33: 0 | F33: 0 | G33: 0.28147054 | H33: 0 | I33: 0 | J33: 0 | K33: 0 | L33: 0 | M33: 0 | N33: 0 | O33: 0 | P33: 0 | Q33: 0
A34: D3 | B34: 0 | C34: 0 | D34: 0 | E34: 0 | F34: 3.8865645e-08 | G34: 0.00070792938 | H34: 0 | I34: 0 | J34: 0 | K34: 0 | L34: 0 | M34: 0 | N34: 0 | O34: 0 | P34: 0 | Q34: 0
A35: E | B35: 0 | C35: 0 | D35: 0 | E35: 1.6045457e-07 | F35: 0.65786465 | G35: 2.4983243e-06 | H35: 4.3076559e-07 | I35: 0 | J35: 7.082426e-07 | K35: 0 | L35: 0 | M35: 9.7959576e-08 | N35: 0 | O35: 0 | P35: 0 | Q35: 0.003891221
A36: F | B36: 0 | C36: 0 | D36: 0 | E36: 0.073478076 | F36: 4.0689186e-05 | G36: 4.2023053e-05 | H36: 9.5791296e-06 | I36: 0 | J36: 0 | K36: 0 | L36: 6.7484679e-06 | M36: 0 | N36: 0 | O36: 0 | P36: 0 | Q36: 0
A37: G | B37: 0 | C37: 0 | D37: 0 | E37: 0 | F37: 0 | G37: 0 | H37: 0 | I37: 0 | J37: 0.18168307 | K37: 0 | L37: 0 | M37: 5.9907459e-08 | N37: 0 | O37: 0 | P37: 0 | Q37: 0
A38: H | B38: 0 | C38: 0 | D38: 0 | E38: 0 | F38: 0 | G38: 0 | H38: 0 | I38: 0 | J38: 0.00056545289 | K38: 0.99996463 | L38: 0 | M38: 4.7695257e-05 | N38: 0 | O38: 0 | P38: 0.048594923 | Q38: 0
... A47: T | B47: 0 | C47: 0 | D47: 0 | E47: 3.4055098e-07 | F47: 0 | G47: 0 | H47: 0.045580049 | I47: 0 | J47: 0 | K47: 0 | L47: 0 | M47: 0 | N47: 0 | O47: 0 | P47: 0.72004487 | Q47: 0
B48: =+SUM(B27:B47) -> 1 | C48: =+SUM(C27:C47) -> 1 | D48: =+SUM(D27:D47) -> 1 | E48: =+SUM(E27:E47) -> 1 | F48: =+SUM(F27:F47) -> 1 | G48: =+SUM(G27:G47) -> 1 | H48: =+SUM(H27:H47) -> 1 | I48: =+SUM(I27:I47) -> 1 | ... Q48: =+SUM(Q27:Q47) -> 1
A50: Initial total consumption per coicop category
B51: CP01 | C51: CP02 | D51: CP03 | E51: CP041_043 | F51: CP044 | G51: CP045 | H51: CP05 | I51: CP06 | J51: CP071_072 | K51: CP073 | L51: CP08 | M51: CP09 | N51: CP10 | O51: CP11 | P51: CP121 | Q51: CP122_127
B52: 141251.6 | C52: 40426.5 | D52: 63910.3 | E52: 161347.5 | F52: 17236.8 | G52: 37757.1 | H52: 52445.27 | I52: 30993.7 | J52: 108198.8 | K52: 15605.1 | L52: 28209.7 | M52: 70797.8 | N52: 9606.2 | O52: 92562.4 | P52: 21378.63 | Q52: 90876.8 | R52: =+SUM(cons_coicop_initial) -> 982604.2

Sheet covid
A1: 2020 | L1: Source
A3: LFPR gs | B3: 2020 | E3: 2021 | H3: 2022 | L3: Computed KLEMS-adjusted LFPR, based on Eurostat edat_lfs
B4: low | C4: mid | D4: high | E4: low | F4: mid | G4: high | H4: low | I4: mid | J4: high
A5: female | B5: -0.056408198 | C5: -0.03069005 | D5: -0.01748116 | E5: 0.019741292 | F5: 0.020376855 | G5: 0.037318382 | H5: 0.013267893 | I5: 0.011618344 | J5: -0.00010558285
A6: male | B6: -0.029514891 | C6: -0.02080501 | D6: -0.0039245149 | E6: 0.024756791 | F6: 0.024677767 | G6: 0.0092216964 | H6: 0.0095148757 | I6: 0.0087829324 | J6: 0.0022176255
A8: Consumption | B8: 2020 | C8: 2021 | D8: 2022 | L8: Istat, Final consumption expenditure of resident and non-resident households on the economic territory
B9: -0.10977915 | C9: 0.070035318 | D9: 0.13739711
A11: Government consumption | B11: 2020 | C11: 2021 | D11: 2022 | L11: Eurostat, nama_10_gdp
B12: 0.0033942042 | C12: 0.023136315 | D12: 0.0064457643
A14: Exports | B14: 2020 | C14: 2021 | D14: 2022 | L14: Eurostat, nama_10_gdp
B15: -0.13709371 | C15: 0.14085505 | D15: 0.097877736
A17: GFCF | B17: 2020 | C17: 2021 | D17: 2022 | E17: 2023 | L17: Eurostat, nama_10_gdp
B18: -0.07106432 | C18: 0.21543333 | D18: 0.07536156 | E18: 0.084799998
A21: Time2 | B21: 0 | C21: 1 | D21: 2 | E21: 3 | F21: 4 | G21: 5 | H21: 6 | I21: 7 | J21: 8 | K21: 9 | L21: 10 | M21: 11 | N21: 12 | O21: 13
A22: gov | C22: -0.022508933 | D22: -0.023324029 | E22: -0.010782952 | F22: -0.0060011705 | G22: -0.0010477136 | H22: 0.012645008 | I22: 0.002787183 | J22: -0.00019389227 | K22: -0.0042874819 | L22: 0.0033942042 | M22: 0.023136315 | N22: 0.0064457643 | O22: 0.019079849
A23: GFCF | C23: -0.015305524 | D23: -0.098409744 | E23: -0.067291694 | F23: -0.021601333 | G23: 0.019496156 | H23: 0.03847182 | I23: 0.032591412 | J23: 0.032805069 | K23: 0.015792902 | L23: -0.07106432 | M23: 0.21543333 | N23: 0.07536156 | O23: 0.084799998
A24: exp | C24: 0.049328571 | D24: 0.018330119 | E24: 0.0024781082 | F24: 0.025404968 | G24: 0.039856656 | H24: 0.023380541 | I24: 0.053675456 | J24: 0.021295903 | K24: 0.012260525 | L24: -0.13709371 | M24: 0.14085505 | N24: 0.097877736 | O24: 0.0082102889
A25: cons | C25: 0.03222992 | D25: -0.0084244099 | E25: -0.010510836 | F25: 0.0049145471 | G25: 0.021154806 | H25: 0.013174097 | I25: 0.025963167 | J25: 0.019680297 | K25: 0.009639998 | L25: -0.1124341 | M25: 0.075179065 | N25: 0.13143828 | O25: 0.062277817
A27: Output expected shocks
B28: covid shock | C28: covid rebound
A29: A | B29: -0.113609 | C29: 0.111828
A30: B | B30: -0.106128 | C30: 0.115606
A31: C | B31: -0.117868 | C31: 0.125933
A32: C19 | B32: -0.124167 | C32: 0.0976994
A33: C29_30 | B33: -0.119721 | C33: 0.132272
A34: D1 | B34: -0.0927163 | C34: 0.110286
A35: D2 | B35: -0.100635 | C35: 0.0961261
A36: D3 | B36: -0.07889 | C36: 0.165377
A37: E | B37: -0.101382 | C37: 0.110902
A38: F | B38: -0.0454576 | C38: 0.189954
A39: G | B39: -0.103204 | C39: 0.0985951
A40: H49_51 | B40: -0.101124 | C40: 0.0955293
... A49: T | B49: -0.113424 | C49: 0.0432718

Sheet investments
A1: Investment Matrix
B2: A | C2: B | D2: C | E2: C19 | F2: C29_30 | G2: D1 | H2: D2 | I2: D3 | J2: E | K2: F | L2: G | M2: H49_51 | N2: I | O2: J_R_S | P2: K | Q2: L | R2: H_M_N | S2: O | T2: P | U2: Q | V2: T
A3: A | B3: 0.043413299 | C3: 0.00062249142 | D3: 0.00072598691 | E3: 1.0002465e-05 | F3: 0.00149655 | G3: 1.0224543e-05 | H3: 1.0279192e-05 | I3: 1.0289445e-05 | J3: 1.5611137e-05 | K3: 4.5133039e-05 | L3: 3.7500113e-05 | M3: 2.4700363e-05 | N3: 4.3443913e-06 | O3: 0.0023865067 | P3: 0.00044894153 | Q3: 5.0275051e-07 | R3: 0.00069540312 | S3: 8.9097819e-06 | T3: 7.491258e-05 | U3: 0.00052952771 | V3: 0
A4: B | B4: 6.4936897e-06 | C4: 0.05928973 | D4: 0.00085366971 | E4: 1.1761646e-05 | F4: 0.0017597554 | G4: 1.2022782e-05 | H4: 1.2087042e-05 | I4: 1.2099099e-05 | J4: 1.8356742e-05 | K4: 5.3070803e-05 | L4: 4.4095438e-05 | M4: 2.9044534e-05 | N4: 5.1084602e-06 | O4: 0.00083384627 | P4: 0.00052789903 | Q4: 5.9117165e-07 | R4: 0.000817707 | S4: 1.0476788e-05 | T4: 8.8087814e-05 | U4: 0.00062265829 | V4: 0
A5: C | B5: 0.52615539 | C5: 0.18446281 | D5: 0.59809798 | E5: 0.40917184 | F5: 0.29967727 | G5: 0.33421887 | H5: 0.33600523 | I5: 0.33634039 | J5: 0.49758745 | K5: 0.49725702 | L5: 0.20666007 | M5: 0.14593078 | N5: 0.4994738 | O5: 0.24339876 | P5: 0.13062205 | Q5: 0.0063392932 | R5: 0.08308914 | S5: 0.20349553 | T5: 0.37278369 | U5: 0.24723912 | V5: 0
A6: C19 | B6: 0.00040823868 | C6: 0.0005890805 | D6: 0.00091150114 | E6: 0.00089759152 | F6: 0.0013057412 | G6: 0.00026414392 | H6: 0.00026555575 | I6: 0.00026582063 | J6: 0.00039353875 | K6: 0.00041450057 | L6: 0.00018573587 | M6: 0.00012987625 | N6: 0.00038689136 | O6: 0.00069662486 | P6: 0.00042299172 | Q6: 5.2320762e-06 | R6: 0.0005635878 | S6: 0.00016275817 | T6: 0.00034026269 | U6: 0.0005705068 | V6: 0
A7: C29_30 | B7: 0.045980634 | C7: 0.010610364 | D7: 0.027794606 | E7: 0.0031060816 | F7: 0.24816701 | G7: 0.0055381912 | H7: 0.0055677922 | I7: 0.005573346 | J7: 0.092373231 | K7: 0.17042138 | L7: 0.067313586 | M7: 0.65512494 | N7: 0.027706202 | O7: 0.014605156 | P7: 0.01467482 | Q7: 0.0017102917 | R7: 0.071795521 | S7: 0.03869918 | T7: 0.030793635 | U7: 0.020468052 | V7: 0
A8: D1 | B8: 5.438523e-05 | C8: 0.0061303305 | D8: 0.0071495599 | E8: 9.8504834e-05 | F8: 0.014738109 | G8: 0.0081560416 | H8: 0.00010123006 | I8: 0.00010133103 | J8: 0.00015373935 | K8: 0.00044447271 | L8: 0.00036930322 | M8: 0.00024325056 | N8: 4.278381e-05 | O8: 0.0069835368 | P8: 0.0044212014 | Q8: 4.9511153e-06 | R8: 0.006848369 | S8: 8.7744033e-05 | T8: 0.0007377433 | U8: 0.0052148187 | V8: 0
A9: D2 | B9: 1.8491339e-05 | C9: 0.0020843531 | D9: 0.0024308978 | E9: 3.3492298e-05 | F9: 0.0050110548 | G9: 3.4235905e-05 | H9: 0.0027879302 | I9: 3.4453224e-05 | J9: 5.2272401e-05 | K9: 0.00015112367 | L9: 0.00012556555 | M9: 8.2706807e-05 | N9: 1.4546779e-05 | O9: 0.0023744489 | P9: 0.0015032378 | Q9: 1.6834121e-06 | R9: 0.0023284909 | S9: 2.9833554e-05 | T9: 0.00025083762 | U9: 0.001773073 | V9: 0
A10: D3 | B10: 1.1799358e-05 | C10: 0.0013300295 | D10: 0.0015511604 | E10: 2.1371497e-05 | F10: 0.0031975633 | G10: 2.1845994e-05 | H10: 2.1962758e-05 | I10: 0.0017807579 | J10: 3.3355115e-05 | K10: 9.6432294e-05 | L10: 8.0123607e-05 | M10: 5.2775366e-05 | N10: 9.2823268e-06 | O10: 0.0015151402 | P10: 0.00095921884 | Q10: 1.0741883e-06 | R10: 0.0014858144 | S10: 1.9036846e-05 | T10: 0.00016005995 | U10: 0.0011314011 | V10: 0
A11: E | B11: 1.6261043e-05 | C11: 0.001832953 | D11: 0.0021376999 | E11: 2.945269e-05 | F11: 0.0044066564 | G11: 3.0106609e-05 | H11: 3.0267525e-05 | I11: 3.0297717e-05 | J11: 0.0037233812 | K11: 0.00013289619 | L11: 0.00011042071 | M11: 7.2731289e-05 | N11: 1.2792248e-05 | O11: 0.0020880594 | P11: 0.0013219278 | Q11: 1.4803707e-06 | R11: 0.0020476446 | S11: 2.6235239e-05 | T11: 0.00022058334 | U11: 0.0015592173 | V11: 0
A12: F | B12: 0.35396923 | C12: 0.54070718 | D12: 0.1135796 | E12: 0.5307976 | F12: 0.034085978 | G12: 0.55473101 | H12: 0.55769599 | I12: 0.55825228 | J12: 0.33343269 | K12: 0.26631723 | L12: 0.1132676 | M12: 0.074367824 | N12: 0.42338074 | O12: 0.13272684 | P12: 0.37547419 | Q12: 0.9229628 | R12: 0.17476138 | S12: 0.64268914 | T12: 0.3990824 | U12: 0.43423526 | V12: 0
A13: G | B13: 0.0010039665 | C13: 0.11316761 | D13: 0.13198287 | E13: 0.0018184267 | F13: 0.27206959 | G13: 0.0018588 | H13: 0.0018687351 | I13: 0.0018705991 | J13: 0.0028380713 | K13: 0.0082050901 | L13: 0.55221267 | M13: 0.0044904732 | N13: 0.00078980105 | O13: 0.12891804 | P13: 0.081616611 | Q13: 9.1398968e-05 | R13: 0.1264228 | S13: 0.0016197793 | T13: 0.013618947 | U13: 0.096267006 | V13: 0
